<?xml version="1.0"?>
<robot xmlns:xacro="http://ros.org/wiki/xacro">

<xacro:if value="${COGIMON_LEFT_LEG}" >

<!-- LINKS -->
<link name ="LHipMot">
    <inertial>
      <origin xyz="${-4.1435899e+01*mmTom} ${-2.4099021e-01*mmTom} ${-6.7437774e+01*mmTom}" rpy="0 0 0"/>
      <mass value="2.0936467"/>
      <inertia ixx="${2.0328644e+04*mm2Tom2}"  ixy="${1.2836757e+01*mm2Tom2}"  ixz="${-7.1832791e+03*mm2Tom2}" iyy="${2.4404941e+04*mm2Tom2}" iyz="${2.2892687e+01*mm2Tom2}" izz="${8.9864540e+03*mm2Tom2}" />
    </inertial>
    <visual>
      <origin xyz="0. 0. 0." rpy="0 0 0."/>
      <material name="green"/>
      <geometry name="RHipMot_visual">
        <mesh filename="package://cogimon_urdf/meshes/HipRoll.stl" scale="${mmTom} ${mmTom} ${mmTom}" />
      </geometry>
    </visual>
    <collision>
      <origin xyz="0.0 0. 0" rpy="0 0 0."/>
      <geometry name="RHipMot_collision">
        <mesh filename="package://cogimon_urdf/meshes/simple/HipRoll.stl" scale="${mmTom} ${mmTom} ${mmTom}" />
      </geometry>             
    </collision>
</link>

<link name ="LThighUpLeg">
    <inertial>   
      <origin xyz="${5.8688639e-01*mmTom} ${-6.2440385e+01*mmTom} ${-8.5057072e+01*mmTom}" rpy="0 0 0"/>
      <mass value="1.6115687"/>     
      <inertia ixx="${1.6169151e+04*mm2Tom2}"  ixy="${-2.1886129e+01*mm2Tom2}"  ixz="${6.0058109e+01*mm2Tom2}" iyy="${1.4437800e+04*mm2Tom2}" iyz="${-2.7173225e+03*mm2Tom2}" izz="${3.9254506e+03*mm2Tom2}" />
    </inertial>
    <visual>
      <origin xyz="0. 0. 0." rpy="0 0 0."/>
      <material name="dark_grey"/>
      <geometry name="LThighUpLeg_visual">
        <mesh filename="package://cogimon_urdf/meshes/HipPitch.stl" scale="${mmTom} ${mmTom} ${mmTom}" />
      </geometry>
    </visual>
    <collision>
      <origin xyz="0.0 0. 0" rpy="0 0 0."/>
      <geometry name="LThighUpLeg_collision">
        <mesh filename="package://cogimon_urdf/meshes/simple/HipPitch.stl" scale="${mmTom} ${mmTom} ${mmTom}" />
      </geometry>             
    </collision>
</link>

<link name ="LThighLowLeg">
    <inertial>       
      <origin xyz="${-2.1136410e+01*mmTom} ${-4.2862386e+00*mmTom} ${-3.8232267e+01*mmTom}" rpy="0 0 0"/>
      <mass value="1.7454681"/>     
      <inertia ixx="${8.5691728e+03*mm2Tom2}"  ixy="${-1.9828734e+02*mm2Tom2}"  ixz="${-2.2121863e+03*mm2Tom2}" iyy="${9.9794948e+03*mm2Tom2}" iyz="${-4.0039407e+02*mm2Tom2}" izz="${5.2783547e+03*mm2Tom2}" />
    </inertial>
    <visual>
      <origin xyz="0. 0. 0." rpy="0 0 0."/>
      <material name="green"/>
      <geometry name="LThighLowLeg_visual">
        <mesh filename="package://cogimon_urdf/meshes/HipYaw.stl" scale="${mmTom} ${mmTom} ${mmTom}" />
      </geometry>
    </visual>
    <collision>
      <origin xyz="0.0 0. 0" rpy="0 0 0."/>
      <geometry name="LThighLowLeg_collision">
        <mesh filename="package://cogimon_urdf/meshes/simple/HipYaw.stl" scale="${mmTom} ${mmTom} ${mmTom}" />
      </geometry>             
    </collision>
</link>


<!-- JOINTS -->
<joint name="LHipLat" type="revolute">
    <parent link="Waist"/>
    <child link="LHipMot"/>
    <origin xyz="${15.45*mmTom} ${112.0*mmTom} ${-50.0*mmTom}" rpy="0 0 0" />
    <axis xyz="1 0 0" />
    <limit velocity="3.67" effort="176" lower="${-90.*toRad}" upper="${90.*toRad}" />
    <dynamics friction="0" damping="3.0"/>
</joint>

<joint name="LHipSag" type="revolute">
    <parent link="LHipMot"/>
    <child link="LThighUpLeg"/>
    <origin xyz="${-59.*mmTom} ${78.65*mmTom} ${-118.5*mmTom}" rpy="0 0 0" />
    <axis xyz="0 1 0" />
    <limit velocity="3.67" effort="176" lower="${-90.*toRad}" upper="${90.*toRad}" />
    <dynamics friction="0" damping="3.0"/>
</joint>

<joint name="LHipYaw" type="revolute">
    <parent link="LThighUpLeg"/>
    <child link="LThighLowLeg"/>
    <origin xyz="${0.*mmTom} ${-90.*mmTom} ${-256.45*mmTom}" rpy="0 0 0" />
    <axis xyz="0 0 1" />
    <limit velocity="3.67" effort="176" lower="${-90.*toRad}" upper="${90.*toRad}" />
    <dynamics friction="0" damping="3.0"/>
</joint>
</xacro:if>


<xacro:if value="${COGIMON_RIGHT_LEG}" >

<!-- LINKS -->
<link name ="RHipMot">
    <inertial>
      <origin xyz="${-4.1435899e+01*mmTom} ${2.4099021e-01*mmTom} ${-6.7437774e+01*mmTom}" rpy="0 0 0"/>
      <mass value="2.0936467"/>
      <inertia ixx="${2.0328644e+04*mm2Tom2}"  ixy="${-1.2836757e+01*mm2Tom2}"  ixz="${-7.1832791e+03*mm2Tom2}" iyy="${2.4404941e+04*mm2Tom2}" iyz="${-2.2892687e+01*mm2Tom2}" izz="${8.9864540e+03*mm2Tom2}" />
    </inertial>
    <visual>
      <origin xyz="0.0 0 0" rpy="0 0 0"/>
      <material name="green"/>
      <geometry name="RHipMot_visual">
        <mesh filename="package://cogimon_urdf/meshes/HipRoll.stl" scale="${mmTom} ${-mmTom} ${mmTom}" />
      </geometry>
    </visual>
    <collision>
      <origin xyz="0.0 0. 0" rpy="0 0 0."/>
      <geometry name="RHipMot_collision">
        <mesh filename="package://cogimon_urdf/meshes/simple/HipRoll.stl" scale="${mmTom} ${-mmTom} ${mmTom}" />
      </geometry>             
    </collision>
</link>

<link name ="RThighUpLeg">
    <inertial>
      <origin xyz="${5.8688639e-01*mmTom} ${6.2440385e+01*mmTom} ${-8.5057072e+01*mmTom}" rpy="0 0 0"/>
      <mass value="1.6115687"/>
      <inertia ixx="${1.6169151e+04*mm2Tom2}"  ixy="${2.1886129e+01*mm2Tom2}"  ixz="${6.0058109e+01*mm2Tom2}" iyy="${1.4437800e+04*mm2Tom2}" iyz="${2.7173225e+03*mm2Tom2}" izz="${3.9254506e+03*mm2Tom2}" />
    </inertial>
    <visual>
      <origin xyz="0. 0. 0." rpy="0 0 0."/>
      <material name="dark_grey"/>
      <geometry name="RThighUpLeg_visual">
        <mesh filename="package://cogimon_urdf/meshes/HipPitch.stl" scale="${mmTom} ${-mmTom} ${mmTom}" />
      </geometry>
    </visual>
    <collision>
      <origin xyz="0.0 0. 0" rpy="0 0 0."/>
      <geometry name="RThighUpLeg_collision">
        <mesh filename="package://cogimon_urdf/meshes/simple/HipPitch.stl" scale="${mmTom} ${-mmTom} ${mmTom}" />
      </geometry>             
    </collision>
  </link>

<link name ="RThighLowLeg">
    <inertial>   
      <origin xyz="${-2.1136410e+01*mmTom} ${4.2862386e+00*mmTom} ${-3.8232267e+01*mmTom}" rpy="0 0 0"/>
      <mass value="1.7454681"/>     
      <inertia ixx="${8.5691728e+03*mm2Tom2}"  ixy="${1.9828734e+02*mm2Tom2}"  ixz="${-2.2121863e+03*mm2Tom2}" iyy="${9.9794948e+03*mm2Tom2}" iyz="${4.0039407e+02*mm2Tom2}" izz="${5.2783547e+03*mm2Tom2}" />
    </inertial>
    <visual>
      <origin xyz="0. 0. 0." rpy="0 0 0."/>
      <material name="green"/>
      <geometry name="RThighLowLeg_visual">
        <mesh filename="package://cogimon_urdf/meshes/HipYaw.stl" scale="${mmTom} ${-mmTom} ${mmTom}" />
      </geometry>
    </visual>
    <collision>
      <origin xyz="0.0 0. 0" rpy="0 0 0."/>
      <geometry name="RThighLowLeg_collision">
        <mesh filename="package://cogimon_urdf/meshes/simple/HipYaw.stl" scale="${mmTom} ${-mmTom} ${mmTom}" />
      </geometry>             
    </collision>
</link>

<!-- JOINTS -->
<joint name="RHipLat" type="revolute">
    <parent link="Waist"/>
    <child link="RHipMot"/>
    <origin xyz="${15.45*mmTom} ${-112.0*mmTom} ${-50.0*mmTom}" rpy="0 0 0" />
    <axis xyz="1 0 0" />
    <limit velocity="3.67" effort="176" lower="${-90.*toRad}" upper="${90.*toRad}" />
    <dynamics friction="0" damping="3.0"/>
</joint>

<joint name="RHipSag" type="revolute">
    <parent link="RHipMot"/>
    <child link="RThighUpLeg"/>
    <origin xyz="${-59.*mmTom} ${-78.65*mmTom} ${-118.5*mmTom}" rpy="0 0 0" />
    <axis xyz="0 1 0" />
    <limit velocity="3.67" effort="176" lower="${-90.*toRad}" upper="${90.*toRad}" />
    <dynamics friction="0" damping="3.0"/>
</joint>

<joint name="RHipYaw" type="revolute">
    <parent link="RThighUpLeg"/>
    <child link="RThighLowLeg"/>
    <origin xyz="${0.*mmTom} ${90.*mmTom} ${-256.45*mmTom}" rpy="0 0 0" />
    <axis xyz="0 0 1" />
    <limit velocity="3.67" effort="176" lower="${-90.*toRad}" upper="${90.*toRad}" />
    <dynamics friction="0" damping="3.0"/>
</joint>
</xacro:if>



</robot>
