<?xml version="1.0"?>
<robot xmlns:xacro="http://ros.org/wiki/xacro">

<xacro:property name="PI" value="3.14159265359" />
<xacro:property name="PI_2" value="1.57079632679" />
<xacro:property name="SF" value="0.03937" /> <!-- Scale factor for meshes -->

<!-- LINKS -->

<!-- ********************RIGHT LEG******************** -->

<link name ="RHipMot">
    <inertial>
      <origin xyz="-3.269678E-4 -0.023587321 -2.6496509E-4" rpy="0 0 0"/>
      <mass value="${wcf*0.89258227}"/>
      <inertia ixx="${wcf*4.7672294E-4}"  ixy="${wcf*-3.9936567E-6}"  ixz="${wcf*-2.4802574E-6}" iyy="${wcf*5.458038E-4}" iyz="${wcf*-3.3389575E-6}" izz="${wcf*5.126859E-4}" />
    </inertial>
    <visual>
      <origin xyz="0.0 0.023 -0.52" rpy="0 0 ${PI}"/>
      <material name="dark_grey"/>
      <geometry name="RHipMot_visual">
        <mesh filename="package://cogimon_urdf/meshes/Leg0.STL" scale="${SF} ${SF} ${SF}" />
      </geometry>
    </visual>
    <collision>
      <origin xyz="0.0 0.023 -0.52" rpy="0 0 ${PI}"/>
      <geometry name="RHipMot_collision">
        <mesh filename="package://cogimon_urdf/meshes/simple/Leg0.STL" scale="${SF} ${SF} ${SF}" />
      </geometry>             
    </collision>
</link>

  <link name ="RThighUpLeg">
    <inertial>
      <origin xyz="0.0012591632 -0.016896372 -0.058903336" rpy="0 0 0"/>
      <mass value="${wcf*1.0246101}"/>
      <inertia ixx="${wcf*9.165719E-4}"  ixy="${wcf*-1.4449904E-6}"  ixz="${wcf*-1.6685011E-5}" iyy="${wcf*0.00104849584}" iyz="${wcf*2.5492874E-5}" izz="${wcf*6.8637197E-4}" />
    </inertial>
    <visual>
      <origin xyz="0.0 0.0726 -0.52" rpy="0 0 ${PI}"/>
      <material name="dark_grey"/>
      <geometry name="RThighUpLeg_visual">
        <mesh filename="package://cogimon_urdf/meshes/Leg1.STL" scale="${SF} ${SF} ${SF}" />
      </geometry>
    </visual>
    <collision>
      <origin xyz="0.0 0.0726 -0.52" rpy="0 0 ${PI}"/>
      <geometry name="RThighUpLeg_collision">
        <mesh filename="package://cogimon_urdf/meshes/simple/Leg1.STL" scale="${SF} ${SF} ${SF}" />
      </geometry>             
    </collision>
  </link>

  <link name ="RThighLowLeg">
    <inertial>
      <origin xyz="9.8720058E-4 6.7037262E-4 -0.075716843" rpy="0 0 0"/>
      <mass value="${wcf*1.7001134}"/>
      <inertia ixx="${wcf*0.0038979546}"  ixy="${wcf*1.7802399E-6}"  ixz="${wcf*2.6403262E-5}" iyy="${wcf*0.0039360845}" iyz="${wcf*4.522711E-5}" izz="${wcf*9.0218711E-4}" />
    </inertial>
    <visual>
      <origin xyz="0.0 0.0726 -0.4176" rpy="0 0 ${PI}"/>
      <material name="dark_grey"/>
      <geometry name="RThighLowLeg_visual">
        <mesh filename="package://cogimon_urdf/meshes/Leg2.STL" scale="${SF} ${SF} ${SF}" />
      </geometry>
    </visual>
    <collision>
      <origin xyz="0.0 0.0726 -0.4176" rpy="0 0 ${PI}"/>
      <geometry name="RThighLowLeg_collision">
        <mesh filename="package://cogimon_urdf/meshes/simple/Leg2.STL" scale="${SF} ${SF} ${SF}" />
      </geometry>             
    </collision>
  </link>

  <link name ="RLowLeg">
    <inertial>
      <origin xyz="0.0024612666 -0.0053099614 -0.08598948" rpy="0 0 0"/>
      <mass value="${wcf*1.4098179}"/>
      <inertia ixx="${wcf*0.0040604004}"  ixy="${wcf*1.1227206E-5}"  ixz="${wcf*1.2260973E-5}" iyy="${wcf*0.004005652855}" iyz="${wcf*5.1899176E-4}" izz="${wcf*0.0012414054}" />
    </inertial>
    <visual>
      <origin xyz="0.0 0.0726 -0.2942" rpy="0 0 ${PI}"/>
      <material name="dark_grey"/>
      <geometry name="RLowLeg_visual">
        <mesh filename="package://cogimon_urdf/meshes/Leg3.STL" scale="${SF} ${SF} ${SF}" />
      </geometry>
    </visual>
    <collision>
      <origin xyz="0.0 0.0726 -0.2942" rpy="0 0 ${PI}"/>
      <geometry name="RLowLeg_collision">
        <mesh filename="package://cogimon_urdf/meshes/simple/Leg3.STL" scale="${SF} ${SF} ${SF}" />
      </geometry>             
    </collision>
  </link>

  <link name ="RFootmot">
    <inertial>
      <origin xyz="8.8067281E-4 -9.2224881E-4 2.3038476E-4" rpy="0 0 0"/>
      <mass value="${wcf*0.72992131}"/>
      <inertia ixx="${wcf*3.2034425E-4}"  ixy="${wcf*7.6346303E-6}"  ixz="${wcf*2.5430158E-7}" iyy="${wcf*3.6584358E-4}" iyz="${wcf*-3.6889276E-6}" izz="${wcf*3.6065156E-4}" />
    </inertial>
    <visual>
      <origin xyz="0.0 0.0726 -0.0932" rpy="0 0 ${PI}"/>
      <material name="dark_grey"/>
      <geometry name="RFootmot_visual">
        <mesh filename="package://cogimon_urdf/meshes/Leg4.STL" scale="${SF} ${SF} ${SF}" />
      </geometry>
    </visual>
    <collision>
      <origin xyz="0.0 0.0726 -0.0932" rpy="0 0 ${PI}"/>
      <geometry name="RFootmot_collision">
        <mesh filename="package://cogimon_urdf/meshes/simple/Leg4.STL" scale="${SF} ${SF} ${SF}" />
      </geometry>             
    </collision>
  </link>

  <xacro:if value="${GAZEBO_COGIMON_USES_ROUND_FEET}">
    <link name ="RFoot">
      <inertial>
        <origin xyz="0.00969210464 -0.0090460227 -0.043062308" rpy="0 0 0"/>
        <mass value="${wcf*0.66646684}"/>
        <inertia ixx="${wcf*0.0012944808}"  ixy="${wcf*-9.2387693E-5}"  ixz="${wcf*2.0080105E-4}" iyy="${wcf*0.0015851846}" iyz="${wcf*2.7599327E-4}" izz="${wcf*0.0013326766}" />
      </inertial>
      <visual>
        <origin xyz="0.0 0.0726 -0.0932" rpy="0 0 -3.14159265359"/>
        <material name="dark_grey"/>
        <geometry name="RFoot_visual">
          <mesh filename="package://cogimon_urdf/meshes/RoundFoot.STL" scale="0.03937 0.03937 0.03937" />
        </geometry>
      </visual>
      <collision>
        <origin xyz="0.0 0.0726 -0.0932" rpy="0 0 -3.14159265359"/>
        <geometry name="RFoot_collision">
          <mesh filename="package://cogimon_urdf/meshes/simple/RoundFoot.STL" scale="0.03937 0.03937 0.03937" />
        </geometry>             
      </collision>
    </link>
  </xacro:if>
  <xacro:unless value="${GAZEBO_COGIMON_USES_ROUND_FEET}">
    <link name ="RFoot">
      <inertial>
        <origin xyz="0.00969210464 -0.0090460227 -0.043062308" rpy="0 0 0"/>
        <mass value="${wcf*0.66646684}"/>
        <inertia ixx="${wcf*0.0012944808}"  ixy="${wcf*-9.2387693E-5}"  ixz="${wcf*2.0080105E-4}" iyy="${wcf*0.0015851846}" iyz="${wcf*2.7599327E-4}" izz="${wcf*0.0013326766}" />
      </inertial>
    <visual>
     <origin xyz="0.03 0 -0.07" rpy="0 0 0" />
     <geometry>
       <box size="0.2 0.1 0.04" />
     </geometry>
     <material name="dark_gray"/>
   </visual>
   <collision>
     <origin xyz="0.03 0 -0.07" rpy="0 0 0"/>
     <geometry>
       <box size="0.2 0.1 0.04" />
     </geometry>
   </collision>
  </link>
  </xacro:unless>

<!-- ********************LEFT LEG******************** -->
  <link name ="LHipMot">
    <inertial>
      <origin xyz="-3.269678E-4 0.023587321 -2.6496509E-4" rpy="0 0 0"/>
      <mass value="${wcf*0.89258227}"/>
      <inertia ixx="${wcf*4.7672294E-4}"  ixy="${wcf*3.9936567E-6}"  ixz="${wcf*-2.4802574E-6}" iyy="${wcf*5.458038E-4}" iyz="${wcf*3.3389575E-6}" izz="${wcf*5.126859E-4}" />
    </inertial>
    <visual>
      <origin xyz="0.0 -0.023 -0.52" rpy="0 0 ${PI}"/>
      <material name="dark_grey"/>
      <geometry name="RHipMot_visual">
        <mesh filename="package://cogimon_urdf/meshes/Leg0.STL" scale="${SF} -${SF} ${SF}" />
      </geometry>
    </visual>
    <collision>
      <origin xyz="0.0 -0.023 -0.52" rpy="0 0 ${PI}"/>
      <geometry name="RHipMot_collision">
        <mesh filename="package://cogimon_urdf/meshes/simple/Leg0.STL" scale="${SF} -${SF} ${SF}" />
      </geometry>             
    </collision>
  </link>

  <link name ="LThighUpLeg">
    <inertial>
      <origin xyz="0.0012591632 0.016896372 -0.058903336" rpy="0 0 0"/>
      <mass value="${wcf*1.0246101}"/>
      <inertia ixx="${wcf*9.165719E-4}"  ixy="${wcf*1.4449904E-6}"  ixz="${wcf*-1.6685011E-5}" iyy="${wcf*0.00104849584}" iyz="${wcf*-2.5492874E-5}" izz="${wcf*6.8637197E-4}" />
    </inertial>
    <visual>
      <origin xyz="0.0 -0.0726 -0.52" rpy="0 0 ${PI}"/>
      <material name="dark_grey"/>
      <geometry name="LThighUpLeg_visual">
        <mesh filename="package://cogimon_urdf/meshes/Leg1.STL" scale="${SF} -${SF} ${SF}" />
      </geometry>
    </visual>
    <collision>
      <origin xyz="0.0 -0.0726 -0.52" rpy="0 0 ${PI}"/>
      <geometry name="LThighUpLeg_collision">
        <mesh filename="package://cogimon_urdf/meshes/simple/Leg1.STL" scale="${SF} -${SF} ${SF}" />
      </geometry>             
    </collision>
  </link>

  <link name ="LThighLowLeg">
    <inertial>
      <origin xyz="9.8720058E-4 -6.7037262E-4 -0.075716843" rpy="0 0 0"/>
      <mass value="${wcf*1.7001134}"/>
      <inertia ixx="${wcf*0.0038979546}"  ixy="${wcf*-1.7802399E-6}"  ixz="${wcf*2.6403262E-5}" iyy="${wcf*0.0039360845}" iyz="${wcf*-4.5227110E-5}" izz="${wcf*9.0218711E-4}" />
    </inertial>
    <visual>
      <origin xyz="0.0 -0.0726 -0.4176" rpy="0 0 ${PI}"/>
      <material name="dark_grey"/>
      <geometry name="LThighLowLeg_visual">
        <mesh filename="package://cogimon_urdf/meshes/Leg2.STL" scale="${SF} -${SF} ${SF}" />
      </geometry>
    </visual>
    <collision>
      <origin xyz="0.0 -0.0726 -0.4176" rpy="0 0 ${PI}"/>
      <geometry name="LThighLowLeg_collision">
        <mesh filename="package://cogimon_urdf/meshes/simple/Leg2.STL" scale="${SF} -${SF} ${SF}" />
      </geometry>             
    </collision>
  </link>

  <link name ="LLowLeg">
    <inertial>
      <origin xyz="0.0024612666 0.0053099614 -0.085989484" rpy="0 0 0"/>
      <mass value="${wcf*1.4098179}"/>
      <inertia ixx="${wcf*0.0040604004}"  ixy="${wcf*-1.1227206E-5}"  ixz="${wcf*1.2260973E-5}" iyy="${wcf*0.004005652855}" iyz="${wcf*-5.1899176E-4}" izz="${wcf*0.0012414054}" />
    </inertial>
    <visual>
      <origin xyz="0.0 -0.0726 -0.2942" rpy="0 0 ${PI}"/>
      <material name="dark_grey"/>
      <geometry name="LLowLeg_visual">
        <mesh filename="package://cogimon_urdf/meshes/Leg3.STL" scale="${SF} -${SF} ${SF}" />
      </geometry>
    </visual>
    <collision>
      <origin xyz="0.0 -0.0726 -0.2942" rpy="0 0 ${PI}"/>
      <geometry name="LLowLeg_collision">
        <mesh filename="package://cogimon_urdf/meshes/simple/Leg3.STL" scale="${SF} -${SF} ${SF}" />
      </geometry>             
    </collision>
  </link>

  <link name ="LFootmot">
    <inertial>
      <origin xyz="8.8067281E-4 9.2224881E-4 2.3038476E-4" rpy="0 0 0"/>
      <mass value="${wcf*0.72992131}"/>
      <inertia ixx="${wcf*3.2034425E-4}"  ixy="${wcf*-7.6346303E-6}"  ixz="${wcf*2.5430158E-7}" iyy="${wcf*3.6584358E-4}" iyz="${wcf*3.6889276E-6}" izz="${wcf*3.6065156E-4}" />
    </inertial>
    <visual>
      <origin xyz="0.0 -0.0726 -0.0932" rpy="0 0 ${PI}"/>
      <material name="dark_grey"/>
      <geometry name="LFootmot_visual">
        <mesh filename="package://cogimon_urdf/meshes/Leg4.STL" scale="${SF} -${SF} ${SF}" />
      </geometry>
    </visual>
    <collision>
      <origin xyz="0.0 -0.0726 -0.0932" rpy="0 0 ${PI}"/>
      <geometry name="LFootmot_collision">
        <mesh filename="package://cogimon_urdf/meshes/simple/Leg4.STL" scale="${SF} -${SF} ${SF}" />
      </geometry>             
    </collision>
  </link>

  <xacro:if value="${GAZEBO_COGIMON_USES_ROUND_FEET}">
    <link name ="LFoot">
      <inertial>
        <origin xyz="0.0096921046 0.0090460227 -0.043062308" rpy="0 0 0"/>
        <mass value="${wcf*0.66646684}"/>
        <inertia ixx="${wcf*0.0012944808}"  ixy="${wcf*9.2387693E-5}"  ixz="${wcf*2.0080105E-4}" iyy="${wcf*0.0015851846}" iyz="${wcf*-2.7599327E-4}" izz="${wcf*0.0013326766}" />
      </inertial>
      <visual>
        <origin xyz="0.0 -0.0726 -0.0932" rpy="0 0 -3.14159265359"/>
        <material name="dark_grey"/>
        <geometry name="LFoot_visual">
          <mesh filename="package://cogimon_urdf/meshes/RoundFoot.STL" scale="0.03937 -0.03937 0.03937" />
        </geometry>
      </visual>
      <collision>
        <origin xyz="0.0 -0.0726 -0.0932" rpy="0 0 -3.14159265359"/>
        <geometry name="LFoot_collision">
          <mesh filename="package://cogimon_urdf/meshes/simple/RoundFoot.STL" scale="0.03937 -0.03937 0.03937" />
        </geometry>             
      </collision>
    </link>
  </xacro:if>
  <xacro:unless value="${GAZEBO_COGIMON_USES_ROUND_FEET}">
    <link name ="LFoot">
      <inertial>
        <origin xyz="0.0096921046 0.0090460227 -0.043062308" rpy="0 0 0"/>
        <mass value="${wcf*0.66646684}"/>
        <inertia ixx="${wcf*0.0012944808}"  ixy="${wcf*9.2387693E-5}"  ixz="${wcf*2.0080105E-4}" iyy="${wcf*0.0015851846}" iyz="${wcf*-2.7599327E-4}" izz="${wcf*0.0013326766}" />
      </inertial>
      <visual>
       <origin xyz="0.03 0 -0.07" rpy="0 0 0" />
       <geometry>
         <box size="0.2 0.1 0.04" />
       </geometry>
       <material name="dark_gray"/>
     </visual>
     <collision>
       <origin xyz="0.03 0 -0.07" rpy="0 0 0"/>
       <geometry>
         <box size="0.2 0.1 0.04" />
       </geometry>
     </collision>
    </link>
  </xacro:unless>
  
<!-- JOINTS -->

<!-- ********************RIGHT LEG******************** -->

  <joint name="RHipSag" type="revolute">
    <parent link="Waist"/>
    <child link="RHipMot"/>
    <origin xyz="0.0 -0.023 0.0" rpy="0 0 0" />
    <axis xyz="0 1 0" />
    <limit velocity="4.0" effort="50" lower="-1.9199" upper="0.7854" />
    <dynamics friction="0" damping="3.0"/>
  </joint>

  <joint name="RHipLat" type="revolute">
    <parent link="RHipMot"/>
    <child link="RThighUpLeg"/>
    <origin xyz="0.0 -0.0496 0.0" rpy="0 0 0" />
    <axis xyz="1 0 0" />
    <limit velocity="4.0" effort="50" lower="-1.0472" upper="0.4363" />
    <dynamics friction="0" damping="3.0"/>
  </joint>

  <joint name="RHipYaw" type="revolute">
    <parent link="RThighUpLeg"/>
    <child link="RThighLowLeg"/>
    <origin xyz="0.0 0.0 -0.1024" rpy="0 0 0" />
    <axis xyz="0 0 1" />
    <limit velocity="4.0" effort="50" lower="-0.8727" upper="0.8727" />
    <dynamics friction="0" damping="3.0"/>
  </joint>

  <joint name="RKneeSag" type="revolute">
    <parent link="RThighLowLeg"/>
    <child link="RLowLeg"/>
    <origin xyz="0.0 0.0 -0.1234" rpy="0 0 0" />
    <axis xyz="0 1 0" />
    <limit velocity="4.0" effort="50" lower="-0.1745" upper="1.9199" />
    <dynamics friction="0" damping="3.0"/>
  </joint>

  <joint name="RAnkLat" type="revolute">
    <parent link="RLowLeg"/>
    <child link="RFootmot"/>
    <origin xyz="0.0 0.0 -0.201" rpy="0 0 0" />
    <axis xyz="1 0 0" />
    <limit velocity="4.0" effort="50" lower="-0.6109" upper="0.6109" />
    <dynamics friction="0" damping="3.0"/> 
  </joint>

  <joint name="RAnkSag" type="revolute">
      <parent link="RFootmot"/>
      <child link="RFoot"/>
      <origin xyz="0.0 0.0 0.0" rpy="0 0 0" />
      <axis xyz="0 1 0" />
      <limit velocity="4.0" effort="50" lower="-1.2217" upper="1.2217" />
      <dynamics friction="0" damping="3.0"/>
  </joint>

<!-- ********************LEFT LEG******************** -->

  <joint name="LHipSag" type="revolute">
    <parent link="Waist"/>
    <child link="LHipMot"/>
    <origin xyz="0.0 0.023 0.0" rpy="0 0 0" />
    <axis xyz="0 1 0" />
    <limit velocity="4.0" effort="50" lower="-1.9199" upper="0.7854" />
    <dynamics friction="0" damping="3.0"/>
  </joint>

  <joint name="LHipLat" type="revolute">
    <parent link="LHipMot"/>
    <child link="LThighUpLeg"/>
    <origin xyz="0.0 0.0496 0.0" rpy="0 0 0" />
    <axis xyz="1 0 0" />
    <limit velocity="4.0" effort="50" lower="-0.4363" upper="1.0472" />
    <dynamics friction="0" damping="3.0"/>
  </joint>

  <joint name="LHipYaw" type="revolute">
    <parent link="LThighUpLeg"/>
    <child link="LThighLowLeg"/>
    <origin xyz="0.0 0.0 -0.1024" rpy="0 0 0" />
    <axis xyz="0 0 1" />
    <limit velocity="4.0" effort="50" lower="-0.8727" upper="0.8727" />
    <dynamics friction="0" damping="3.0"/>
  </joint>

  <joint name="LKneeSag" type="revolute">
    <parent link="LThighLowLeg"/>
    <child link="LLowLeg"/>
    <origin xyz="0.0 0.0 -0.1234" rpy="0 0 0" />
    <axis xyz="0 1 0" />
    <limit velocity="4.0" effort="50" lower="-0.1745" upper="1.9199" />
    <dynamics friction="0" damping="3.0"/>
  </joint>

  <joint name="LAnkLat" type="revolute">
    <parent link="LLowLeg"/>
    <child link="LFootmot"/>
    <origin xyz="0.0 0.0 -0.201" rpy="0 0 0" />
    <axis xyz="1 0 0" />
    <limit velocity="4.0" effort="50" lower="-0.6109" upper="0.6109" />
    <dynamics friction="0" damping="3.0"/>
  </joint>

  <joint name="LAnkSag" type="revolute">
      <parent link="LFootmot"/>
      <child link="LFoot"/>
      <origin xyz="0.0 0.0 0.0" rpy="0 0 0" />
      <axis xyz="0 1 0" />
      <limit velocity="4.0" effort="50" lower="-1.2217" upper="1.2217" />
      <dynamics friction="0" damping="3.0"/>
  </joint>

</robot>
