<?xml version="1.0"?>
<robot xmlns:xacro="http://ros.org/wiki/xacro">

<link name="DWYTorso">
    <inertial>
      <origin rpy="0 0 0" xyz="-0.059646212 0.0014305062 0.042741527"/>
      <mass value="1.2512295e+01"/>
      <inertia ixx="0.21021617" ixy="-0.00015527214" ixz="-0.050216602" iyy="0.19982996" iyz="-0.00029204792" izz="0.14025094"/>
    </inertial>
    <visual>
      <origin rpy="0 0 0" xyz="0.0 0.0 0.0"/>
      <geometry name="DWYTorso_visual">
        <mesh filename="package://walkman_urdf/meshes/Chest.STL" scale="0.001 0.001 0.001"/>
      </geometry>
      <material name="dark_grey"/>
    </visual>
    <collision>
      <origin rpy="0 0 0" xyz="0.0 0.0 0.0"/>
      <geometry name="DWYTorso_collision">
        <mesh filename="package://walkman_urdf/meshes/simple/Chest.STL" scale="0.001 0.001 0.001"/>
      </geometry>
    </collision>
  </link>

<joint name="WaistYaw" type="revolute">
    <parent link="Waist"/>
    <child link="DWYTorso"/>
    <origin rpy="0 0 0" xyz="-0.05 0 0.15"/>
    <axis xyz="0 0 1"/>
    <limit effort="120" lower="-1.74532925199" upper="1.74532925199" velocity="6.283"/>
    <dynamics damping="3.0" friction="0"/>
</joint>

<!-- RIGHT ARM -->
  <link name="RShp">
    <inertial>
      <origin rpy="0 0 0" xyz="-0.0074457212 -0.03410796 0.00010978102"/>
      <mass value="1.9628675"/>
      <inertia ixx="0.0053547717" ixy="-0.00036428926" ixz="1.5089568e-05" iyy="0.0033923328" iyz="-5.5692312e-05" izz="0.0068921413"/>
    </inertial>
    <visual>
      <origin rpy="0 0 0" xyz="0 0 0"/>
      <geometry name="RShp_visual">
        <mesh filename="package://walkman_urdf/meshes/ShoulderPitch.STL" scale="0.001 0.001 0.001"/>
      </geometry>
      <material name="dark_grey"/>
    </visual>
    <collision>
      <origin rpy="0 0 0" xyz="0 0 0"/>
      <geometry name="RShp_collision">
        <mesh filename="package://walkman_urdf/meshes/simple/ShoulderPitch.STL" scale="0.001 0.001 0.001"/>
      </geometry>
    </collision>
  </link>
  <link name="RShr">
    <inertial>
      <origin rpy="0 0 0" xyz="0.058142302 -5.7450803e-05 -0.077477683"/>
      <mass value="1.8595811"/>
      <inertia ixx="0.013776643" ixy="-3.7788675e-05" ixz="0.0037690171" iyy="0.015677464" iyz="9.4893549e-06" izz="0.0046317657"/>
    </inertial>
    <visual>
      <origin rpy="0 0 0" xyz="0 0 0"/>
      <geometry name="RShr_visual">
        <mesh filename="package://walkman_urdf/meshes/ShoulderRoll.STL" scale="0.001 0.001 0.001"/>
      </geometry>
      <material name="dark_grey"/>
    </visual>
    <collision>
      <origin rpy="0 0 0" xyz="0 0 0"/>
      <geometry name="RShr_collision">
        <mesh filename="package://walkman_urdf/meshes/simple/ShoulderRoll.STL" scale="0.001 0.001 0.001"/>
      </geometry>
    </collision>
  </link>
  <link name="RShy">
    <inertial>
      <origin rpy="0 0 0" xyz="0.014625194 -0.0008172672 -0.028333545"/>
      <mass value="1.6678109"/>
      <inertia ixx="0.0064480435" ixy="0.00015639093" ixz="0.0012205359" iyy="0.0073372077" iyz="-8.9941532e-05" izz="0.0036738448"/>
    </inertial>
    <visual>
      <origin rpy="0 0 0" xyz="0 0 0"/>
      <geometry name="RShy_visual">
        <mesh filename="package://walkman_urdf/meshes/ShoulderYaw.STL" scale="0.001 0.001 0.001"/>
      </geometry>
      <material name="dark_grey"/>
    </visual>
    <collision>
      <origin rpy="0 0 0" xyz="0 0 0"/>
      <geometry name="RShy_collision">
        <mesh filename="package://walkman_urdf/meshes/simple/ShoulderYaw.STL" scale="0.001 0.001 0.001"/>
      </geometry>
    </collision>
  </link>
  <link name="RElb">
    <inertial>
      <origin rpy="0 0 0" xyz="-0.0076833067 0.040302205 -0.043492779"/>
      <mass value="1.3157289"/>
      <inertia ixx="0.004330394" ixy="0.00011737391" ixz="-0.00041923199" iyy="0.0038539919" iyz="0.00079573038" izz="0.0017594689"/>
    </inertial>
    <visual>
      <origin rpy="0 0 0" xyz="0 0 0"/>
      <geometry name="RElb_visual">
        <mesh filename="package://walkman_urdf/meshes/Elbow.STL" scale="0.001 0.001 0.001"/>
      </geometry>
      <material name="dark_grey"/>
    </visual>
    <collision>
      <origin rpy="0 0 0" xyz="0 0 0"/>
      <geometry name="RElb_collision">
        <mesh filename="package://walkman_urdf/meshes/simple/Elbow.STL" scale="0.001 0.001 0.001"/>
      </geometry>
    </collision>
  </link>
  <link name="RForearm">
    <inertial>
      <origin rpy="0 0 0" xyz="-0.00011079615 -0.011590836 -0.07816026"/>
      <mass value="1.4908547"/>
      <inertia ixx="0.0085692128" ixy="-1.7856252e-05" ixz="1.9379365e-05" iyy="0.0077454159" iyz="0.00032860094" izz="0.0027441921"/>
    </inertial>
    <visual>
      <origin rpy="0 0 0" xyz="0 0 0"/>
      <geometry name="RForearm_visual">
        <mesh filename="package://walkman_urdf/meshes/Forearm.STL" scale="0.001 0.001 0.001"/>
      </geometry>
      <material name="dark_grey"/>
    </visual>
    <collision>
      <origin rpy="0 0 0" xyz="0 0 0"/>
      <geometry name="RForearm_collision">
        <mesh filename="package://walkman_urdf/meshes/simple/Forearm.STL" scale="0.001 0.001 0.001"/>
      </geometry>
    </collision>
  </link>
  <link name="RWrMot2">
    <inertial>
      <origin rpy="0 0 0" xyz="-4.6502396e-06 0.038014094 -0.069926878"/>
      <mass value="1.1263612"/>
      <inertia ixx="0.0051871784" ixy="-2.724437e-05" ixz="2.2833496e-06" iyy="0.0048037789" iyz="0.00072165653" izz="0.0012771388"/>
    </inertial>
    <visual>
      <origin rpy="0 0 0" xyz="0 0 0"/>
      <geometry name="RWrMot2_visual">
        <mesh filename="package://walkman_urdf/meshes/ForearmPitch.STL" scale="0.001 0.001 0.001"/>
      </geometry>
      <material name="dark_grey"/>
    </visual>
    <collision>
      <origin rpy="0 0 0" xyz="0 0 0"/>
      <geometry name="RWrMot2_collision">
        <mesh filename="package://walkman_urdf/meshes/simple/ForearmPitch.STL" scale="0.001 0.001 0.001"/>
      </geometry>
    </collision>
  </link>
  <link name="RWrMot3">
    <inertial>
      <origin rpy="0 0 0" xyz="0 0 0.03127057"/>
      <mass value="2.7966428e-01"/>
      <inertia ixx="0.00014415192" ixy="9.8651826e-08" ixz="0" iyy="0.0001441701" iyz="0" izz="6.0500616e-05"/>
    </inertial>
    <visual>
      <origin rpy="0 0 0" xyz="0 0 0"/>
      <geometry name="RWrMot3_visual">
        <mesh filename="package://walkman_urdf/meshes/ForearmYaw.STL" scale="0.001 0.001 0.001"/>
      </geometry>
      <material name="blue"/>
    </visual>
    <collision>
      <origin rpy="0 0 0" xyz="0 0 0"/>
      <geometry name="RWrMot3_collision">
        <mesh filename="package://walkman_urdf/meshes/simple/ForearmYaw.STL" scale="0.001 0.001 0.001"/>
      </geometry>
    </collision>
  </link>
  <joint name="RShSag" type="revolute">
    <parent link="DWYTorso"/>
    <child link="RShp"/>
    <origin rpy="-0.174533 0 0.5235988" xyz="0.0457475 -0.169137 0.155126"/>
    <axis xyz="0 1 0"/>
    <limit effort="147" lower="-3.359" upper="1.606" velocity="6.283"/>
    <dynamics damping="3.0" friction="0"/>
  </joint>
  <joint name="RShLat" type="revolute">
    <parent link="RShp"/>
    <child link="RShr"/>
    <origin rpy="0.1745327 0 0" xyz="-0.09015 -0.062 0"/>
    <axis xyz="1 0 0"/>
    <limit effort="120" lower="-3.43" upper="-0.004" velocity="6.283"/>
    <dynamics damping="3.0" friction="0"/>
  </joint>
  <joint name="RShYaw" type="revolute">
    <parent link="RShr"/>
    <child link="RShy"/>
    <origin rpy="0 0 0" xyz="0.09015 0 -0.21815"/>
    <axis xyz="0 0 1"/>
    <limit effort="147" lower="-2.55" upper="2.55" velocity="6.283"/>
    <dynamics damping="3.0" friction="0"/>
  </joint>
  <joint name="RElbj" type="revolute">
    <parent link="RShy"/>
    <child link="RElb"/>
    <origin rpy="0 0 0" xyz="0.045 -0.05515 -0.074"/>
    <axis xyz="0 1 0"/>
    <limit effort="147" lower="-2.488" upper="0.292" velocity="6.283"/>
    <dynamics damping="3.0" friction="0"/>
  </joint>
  <joint name="RForearmPlate" type="revolute">
    <parent link="RElb"/>
    <child link="RForearm"/>
    <origin rpy="0 0 0" xyz="-0.015 0.05515 -0.095"/>
    <axis xyz="0 0 1"/>
    <limit effort="55" lower="-2.55" upper="2.55" velocity="6.283"/>
    <dynamics damping="0.03" friction="0"/>
  </joint>
  <joint name="RWrj1" type="revolute">
    <parent link="RForearm"/>
    <child link="RWrMot2"/>
    <origin rpy="0 0 0" xyz="0 -0.049 -0.156"/>
    <axis xyz="0 1 0"/>
    <limit effort="55" lower="-1.542" upper="1.508" velocity="6.283"/>
    <dynamics damping="0.03" friction="0"/>
  </joint>
  <joint name="RWrj2" type="revolute">
    <parent link="RWrMot2"/>
    <child link="RWrMot3"/>
    <origin rpy="0 0 0" xyz="0 0.049 -0.174"/>
    <axis xyz="0 0 1"/>
    <limit effort="27" lower="-2.55" upper="2.55" velocity="6.283"/>
    <dynamics damping="0.03" friction="0"/>
  </joint>
  <!-- LEFT ARM -->
  <link name="LShp">
    <inertial>
      <origin rpy="0 0 0" xyz="-0.0074457212 0.03410796 0.00010978102"/>
      <mass value="1.9628675"/>
      <inertia ixx="0.0053547717" ixy="0.00036428926" ixz="1.5089568e-05" iyy="0.0033923328" iyz="5.5692312e-05" izz="0.0068921413"/>
    </inertial>
    <visual>
      <origin rpy="0 0 0" xyz="0 0 0"/>
      <geometry name="LShp_visual">
        <mesh filename="package://walkman_urdf/meshes/ShoulderPitch.STL" scale="0.001 -0.001 0.001"/>
      </geometry>
      <material name="dark_grey"/>
    </visual>
    <collision>
      <origin rpy="0 0 0" xyz="0 0 0"/>
      <geometry name="LShp_collision">
        <mesh filename="package://walkman_urdf/meshes/simple/ShoulderPitch.STL" scale="0.001 -0.001 0.001"/>
      </geometry>
    </collision>
  </link>
  <link name="LShr">
    <inertial>
      <origin rpy="0 0 0" xyz="0.058142302 5.7450803e-05 -0.077477683"/>
      <mass value="1.8595811"/>
      <inertia ixx="0.013776643" ixy="3.7788675e-05" ixz="0.0037690171" iyy="0.015677464" iyz="-9.4893549e-06" izz="0.0046317657"/>
    </inertial>
    <visual>
      <origin rpy="0 0 0" xyz="0 0 0"/>
      <geometry name="LShr_visual">
        <mesh filename="package://walkman_urdf/meshes/ShoulderRoll.STL" scale="0.001 -0.001 0.001"/>
      </geometry>
      <material name="dark_grey"/>
    </visual>
    <collision>
      <origin rpy="0 0 0" xyz="0 0 0"/>
      <geometry name="LShr_collision">
        <mesh filename="package://walkman_urdf/meshes/simple/ShoulderRoll.STL" scale="0.001 -0.001 0.001"/>
      </geometry>
    </collision>
  </link>
  <link name="LShy">
    <inertial>
      <origin rpy="0 0 0" xyz="0.014625194 0.0008172672 -0.028333545"/>
      <mass value="1.6678109"/>
      <inertia ixx="0.0064480435" ixy="-0.00015639093" ixz="0.0012205359" iyy="0.0073372077" iyz="8.9941532e-05" izz="0.0036738448"/>
    </inertial>
    <visual>
      <origin rpy="0 0 0" xyz="0 0 0"/>
      <geometry name="LShy_visual">
        <mesh filename="package://walkman_urdf/meshes/ShoulderYaw.STL" scale="0.001 -0.001 0.001"/>
      </geometry>
      <material name="dark_grey"/>
    </visual>
    <collision>
      <origin rpy="0 0 0" xyz="0 0 0"/>
      <geometry name="LShy_collision">
        <mesh filename="package://walkman_urdf/meshes/simple/ShoulderYaw.STL" scale="0.001 -0.001 0.001"/>
      </geometry>
    </collision>
  </link>
  <link name="LElb">
    <inertial>
      <origin rpy="0 0 0" xyz="-0.0076833067 -0.040302205 -0.043492779"/>
      <mass value="1.3157289"/>
      <inertia ixx="0.004330394" ixy="-0.00011737391" ixz="-0.00041923199" iyy="0.0038539919" iyz="-0.00079573038" izz="0.0017594689"/>
    </inertial>
    <visual>
      <origin rpy="0 0 0" xyz="0 0 0"/>
      <geometry name="LElb_visual">
        <mesh filename="package://walkman_urdf/meshes/Elbow.STL" scale="0.001 -0.001 0.001"/>
      </geometry>
      <material name="dark_grey"/>
    </visual>
    <collision>
      <origin rpy="0 0 0" xyz="0 0 0"/>
      <geometry name="LElb_collision">
        <mesh filename="package://walkman_urdf/meshes/simple/Elbow.STL" scale="0.001 -0.001 0.001"/>
      </geometry>
    </collision>
  </link>
  <link name="LForearm">
    <inertial>
      <origin rpy="0 0 0" xyz="-0.00011079615 0.011590836 -0.07816026"/>
      <mass value="1.4908547"/>
      <inertia ixx="0.0085692128" ixy="1.7856252e-05" ixz="1.9379365e-05" iyy="0.0077454159" iyz="-0.00032860094" izz="0.0027441921"/>
    </inertial>
    <visual>
      <origin rpy="0 0 0" xyz="0 0 0"/>
      <geometry name="LForearm_visual">
        <mesh filename="package://walkman_urdf/meshes/Forearm.STL" scale="0.001 -0.001 0.001"/>
      </geometry>
      <material name="dark_grey"/>
    </visual>
    <collision>
      <origin rpy="0 0 0" xyz="0 0 0"/>
      <geometry name="LForearm_collision">
        <mesh filename="package://walkman_urdf/meshes/simple/Forearm.STL" scale="0.001 -0.001 0.001"/>
      </geometry>
    </collision>
  </link>
  <link name="LWrMot2">
    <inertial>
      <origin rpy="0 0 0" xyz="-4.6502396e-06 -0.038014094 -0.069926878"/>
      <mass value="1.1263612"/>
      <inertia ixx="0.0051871784" ixy="2.724437e-05" ixz="2.2833496e-06" iyy="0.0048037789" iyz="-0.00072165653" izz="0.0012771388"/>
    </inertial>
    <visual>
      <origin rpy="0 0 0" xyz="0 0 0"/>
      <geometry name="LWrMot2_visual">
        <mesh filename="package://walkman_urdf/meshes/ForearmPitch.STL" scale="0.001 -0.001 0.001"/>
      </geometry>
      <material name="dark_grey"/>
    </visual>
    <collision>
      <origin rpy="0 0 0" xyz="0 0 0"/>
      <geometry name="LWrMot2_collision">
        <mesh filename="package://walkman_urdf/meshes/simple/ForearmPitch.STL" scale="0.001 -0.001 0.001"/>
      </geometry>
    </collision>
  </link>
  <link name="LWrMot3">
    <inertial>
      <origin rpy="0 0 0" xyz="0 0 0.03127057"/>
      <mass value="2.7966428e-01"/>
      <inertia ixx="0.00014415192" ixy="9.8651826e-08" ixz="0" iyy="0.0001441701" iyz="0" izz="6.0500616e-05"/>
    </inertial>
    <visual>
      <origin rpy="0 0 0" xyz="0 0 0"/>
      <geometry name="LWrMot3_visual">
        <mesh filename="package://walkman_urdf/meshes/ForearmYaw.STL" scale="0.001 -0.001 0.001"/>
      </geometry>
      <material name="blue"/>
    </visual>
    <collision>
      <origin rpy="0 0 0" xyz="0 0 0"/>
      <geometry name="LWrMot3_collision">
        <mesh filename="package://walkman_urdf/meshes/simple/ForearmYaw.STL" scale="0.001 -0.001 0.001"/>
      </geometry>
    </collision>
  </link>
  <joint name="LShSag" type="revolute">
    <parent link="DWYTorso"/>
    <child link="LShp"/>
    <origin rpy="0.174533 0 -0.5235988" xyz="0.0457475 0.169137 0.155126"/>
    <axis xyz="0 1 0"/>
    <limit effort="147" lower="-3.352" upper="1.603" velocity="6.283"/>
    <dynamics damping="3.0" friction="0"/>
  </joint>
  <joint name="LShLat" type="revolute">
    <parent link="LShp"/>
    <child link="LShr"/>
    <origin rpy="-0.1745327 0 0" xyz="-0.09015 0.062 0"/>
    <axis xyz="1 0 0"/>
    <limit effort="120" lower="0.037" upper="3.517" velocity="6.283"/>
    <dynamics damping="3.0" friction="0"/>
  </joint>
  <joint name="LShYaw" type="revolute">
    <parent link="LShr"/>
    <child link="LShy"/>
    <origin rpy="0 0 0" xyz="0.09015 0 -0.21815"/>
    <axis xyz="0 0 1"/>
    <limit effort="147" lower="-2.55" upper="2.55" velocity="6.283"/>
    <dynamics damping="3.0" friction="0"/>
  </joint>
  <joint name="LElbj" type="revolute">
    <parent link="LShy"/>
    <child link="LElb"/>
    <origin rpy="0 0 0" xyz="0.045 0.05515 -0.074"/>
    <axis xyz="0 1 0"/>
    <limit effort="147" lower="-2.492" upper="0.298" velocity="6.283"/>
    <dynamics damping="3.0" friction="0"/>
  </joint>
  <joint name="LForearmPlate" type="revolute">
    <parent link="LElb"/>
    <child link="LForearm"/>
    <origin rpy="0 0 0" xyz="-0.015 -0.05515 -0.095"/>
    <axis xyz="0 0 1"/>
    <limit effort="55" lower="-2.55" upper="2.55" velocity="6.283"/>
    <dynamics damping="0.03" friction="0"/>
  </joint>
  <joint name="LWrj1" type="revolute">
    <parent link="LForearm"/>
    <child link="LWrMot2"/>
    <origin rpy="0 0 0" xyz="0 0.049 -0.156"/>
    <axis xyz="0 1 0"/>
    <limit effort="55" lower="-1.562" upper="1.478" velocity="6.283"/>
    <dynamics damping="0.03" friction="0"/>
  </joint>
  <joint name="LWrj2" type="revolute">
    <parent link="LWrMot2"/>
    <child link="LWrMot3"/>
    <origin rpy="0 0 0" xyz="0 -0.049 -0.174"/>
    <axis xyz="0 0 1"/>
    <limit effort="27" lower="-2.55" upper="2.55" velocity="6.283"/>
    <dynamics damping="0.03" friction="0"/>
  </joint>
  <link name="l_wrist">
    <inertial>
      <origin rpy="0 0 0" xyz="8.2161929e-05 0.0026334189 -0.016465877"/>
      <mass value="3.7827821e-01"/>
      <inertia ixx="0.00023321716" ixy="2.3681435e-06" ixz="-1.8039102e-06" iyy="0.00020626291" iyz="3.158829e-05" izz="0.00027399881"/>
    </inertial>
    <visual>
      <origin rpy="3.14159265359 0 0" xyz="0 0 0"/>
      <geometry name="LShp_visual">
        <mesh filename="package://walkman_urdf/meshes/Wrist.STL" scale="0.001 -0.001 0.001"/>
      </geometry>
      <material name="dark_grey"/>
    </visual>
    <collision>
      <origin rpy="3.14159265359 0 0" xyz="0 0 0"/>
      <geometry name="LShp_collision">
        <mesh filename="package://walkman_urdf/meshes/simple/Wrist.STL" scale="0.001 -0.001 0.001"/>
      </geometry>
    </collision>
  </link>
  <link name="r_wrist">
    <inertial>
      <origin rpy="0 0 0" xyz="8.2161929e-05 -0.0026334189 -0.016465877"/>
      <mass value="3.7827821e-01"/>
      <inertia ixx="0.00023321716" ixy="-2.3681435e-06" ixz="-1.8039102e-06" iyy="0.00020626291" iyz="-3.158829e-05" izz="0.00027399881"/>
    </inertial>
    <visual>
      <origin rpy="3.14159265359 0 0" xyz="0 0 0"/>
      <geometry name="RShp_visual">
        <mesh filename="package://walkman_urdf/meshes/Wrist.STL" scale="0.001 0.001 0.001"/>
      </geometry>
      <material name="dark_grey"/>
    </visual>
    <collision>
      <origin rpy="3.14159265359 0 0" xyz="0 0 0"/>
      <geometry name="RShp_collision">
        <mesh filename="package://walkman_urdf/meshes/simple/Wrist.STL" scale="0.001 0.001 0.001"/>
      </geometry>
    </collision>
  </link>
  <joint name="l_wrist_joint" type="fixed">
    <parent link="LWrMot3"/>
    <child link="l_wrist"/>
    <origin rpy="0 0 0" xyz="0 0 0"/>
  </joint>
  <joint name="r_wrist_joint" type="fixed">
    <parent link="RWrMot3"/>
    <child link="r_wrist"/>
    <origin rpy="0 0 0" xyz="0 0 0"/>
  </joint>
  <!-- LINKS -->
  <link name="RSoftHand"/>
  <link name="TCP_R"/>
  <link name="RSoftHandLink">
    <inertial>
      <origin rpy="0 0 0" xyz="0.0020955992 0.0043009755 -0.060792229"/>
      <mass value="1.4"/>
      <inertia ixx="0.0046340021" ixy="-5.6301252e-05" ixz="0.00021001241" iyy="0.0052222303" iyz="0.00020916976" izz="0.0013961628"/>
    </inertial>
    <visual>
      <origin rpy="0.0 0.0 0.0" xyz="0.0 0.0 0.0"/>
      <geometry name="RSoftHandLink_visual">
        <mesh filename="package://walkman_urdf/meshes/SoftHandOpen2.STL" scale="0.001 0.001 0.001"/>
      </geometry>
      <material name="grey"/>
    </visual>
    <collision>
      <origin rpy="0.0 0.0 0.0" xyz="0.0 0.0 0.0"/>
      <geometry name="RSoftHandLink_collision">
        <mesh filename="package://walkman_urdf/meshes/simple/SoftHandOpen2.STL" scale="0.001 0.001 0.001"/>
      </geometry>
    </collision>
  </link>
  <link name="LSoftHand"/>
  <link name="TCP_L"/>
  <link name="LSoftHandLink">
    <inertial>
      <origin rpy="0 0 0" xyz="0.0020955992 -0.0043009755 -0.060792229"/>
      <mass value="1.4"/>
      <inertia ixx="0.0046340021" ixy="5.6301252e-05" ixz="0.00021001241" iyy="0.0052222303" iyz="-0.00020916976" izz="0.0013961628"/>
    </inertial>
    <visual>
      <origin rpy="0.0 0.0 0.0" xyz="0.0 0.0 0.0"/>
      <geometry name="LSoftHandLink_visual">
        <mesh filename="package://walkman_urdf/meshes/SoftHandOpen2.STL" scale="0.001 -0.001 0.001"/>
      </geometry>
      <material name="grey"/>
    </visual>
    <collision>
      <origin rpy="0.0 0.0 0.0" xyz="0.0 0.0 0.0"/>
      <geometry name="LSoftHandLink_collision">
        <mesh filename="package://walkman_urdf/meshes/simple/SoftHandOpen2.STL" scale="0.001 -0.001 0.001"/>
      </geometry>
    </collision>
  </link>
  <!-- JOINTS -->
  <joint name="r_handj" type="fixed">
    <parent link="r_wrist"/>
    <child link="RSoftHandLink"/>
    <origin rpy="0 0 0" xyz="0 0 -0.0395"/>
  </joint>
  <joint name="r_handj2" type="fixed">
    <parent link="RSoftHandLink"/>
    <child link="RSoftHand"/>
    <origin rpy="0 0 0" xyz="0 0.041 -0.1005"/>
  </joint>
  <joint name="l_handj" type="fixed">
    <parent link="l_wrist"/>
    <child link="LSoftHandLink"/>
    <origin rpy="0 0 0" xyz="0 0 -0.0395"/>
  </joint>
  <joint name="l_handj2" type="fixed">
    <parent link="LSoftHandLink"/>
    <child link="LSoftHand"/>
    <origin rpy="0 0 0" xyz="0 -0.041 -0.1005"/>
  </joint>
  <joint name="TCP_Ljoint" type="fixed">
    <parent link="LSoftHand"/>
    <child link="TCP_L"/>
    <origin rpy="1.57079632679 3.14159265359 0" xyz="0.0 0.0 0.0"/>
  </joint>
  <joint name="TCP_Rjoint" type="fixed">
    <parent link="RSoftHand"/>
    <child link="TCP_R"/>
    <origin rpy="-1.57079632679 0 0" xyz="0.0 0.0 0.0"/>
  </joint>

</robot>
